<?xml version="1.0" ?>
<sdf version="1.6">
  <model name="turtlebot3_waffle">  
  <pose>0.0 0.0 0.0 0.0 0.0 0.0</pose>

    <link name="base_footprint"/>

    <link name="base_link">

      <inertial>
        <pose>-0.096 0 0.072 0 0 0</pose> <!-- Scaled by 1.5 -->
        <inertia>
          <ixx>9.4740756e-02</ixx> <!-- Scaled by 1.5^5 -->
          <ixy>0</ixy>
          <ixz>0</ixz>
          <iyy>9.4740756e-02</iyy> <!-- Scaled by 1.5^5 -->
          <iyz>0</iyz>
          <izz>2.5358550e-01</izz> <!-- Scaled by 1.5^5 -->
        </inertia>
        <mass>4.6338414e+00</mass> <!-- Scaled by 1.5^3 -->
      </inertial>

      <collision name="base_collision">
        <pose>-0.096 0 0.072 0 0 0</pose> <!-- Scaled by 1.5 -->
        <geometry>
          <box>
            <size>0.398 0.398 0.134</size> <!-- Scaled by 1.5 -->
          </box>
        </geometry>
      </collision>

      <visual name="base_visual">
        <pose>-0.096 0 0 0 0 0</pose> <!-- Scaled by 1.5 -->
        <geometry>
          <mesh>
            <uri>model://turtlebot3_common/meshes/waffle_base.dae</uri>
            <scale>0.0035 0.0035 0.0035</scale> <!-- Scaled by 1.5 -->
          </mesh>
        </geometry>
      </visual>
    </link>

    <link name="imu_link">
      <sensor name="tb3_imu" type="imu">
        <always_on>true</always_on>
        <update_rate>200</update_rate>
        <imu>
          <angular_velocity>
            <x>
              <noise type="gaussian">
                <mean>0.0</mean>
                <stddev>3e-4</stddev> <!-- Adjusted noise -->
              </noise>
            </x>
            <y>
              <noise type="gaussian">
                <mean>0.0</mean>
                <stddev>3e-4</stddev> <!-- Adjusted noise -->
              </noise>
            </y>
            <z>
              <noise type="gaussian">
                <mean>0.0</mean>
                <stddev>3e-4</stddev> <!-- Adjusted noise -->
              </noise>
            </z>
          </angular_velocity>
          <linear_acceleration>
            <x>
              <noise type="gaussian">
                <mean>0.0</mean>
                <stddev>2.55e-2</stddev> <!-- Adjusted noise -->
              </noise>
            </x>
            <y>
              <noise type="gaussian">
                <mean>0.0</mean>
                <stddev>2.55e-2</stddev> <!-- Adjusted noise -->
              </noise>
            </y>
            <z>
              <noise type="gaussian">
                <mean>0.0</mean>
                <stddev>2.55e-2</stddev> <!-- Adjusted noise -->
              </noise>
            </z>
          </linear_acceleration>
        </imu>
        <plugin name="turtlebot3_imu" filename="libgazebo_ros_imu_sensor.so">
          <ros>
            <!-- <namespace>/tb3</namespace> -->
            <remapping>~/out:=imu</remapping>
          </ros>
        </plugin>
      </sensor>
    </link>

    <link name="base_scan">    
      <inertial>
        <pose>-0.078 0 0.167 0 0 0</pose> <!-- Scaled by 1.5 -->
        <inertia>
          <ixx>0.003375</ixx> <!-- Scaled by 1.5^5 -->
          <ixy>0.000</ixy>
          <ixz>0.000</ixz>
          <iyy>0.003375</iyy> <!-- Scaled by 1.5^5 -->
          <iyz>0.000</iyz>
          <izz>0.003375</izz> <!-- Scaled by 1.5^5 -->
        </inertia>
        <mass>0.385</mass> <!-- Scaled by 1.5^3 -->
      </inertial>

      <collision name="lidar_sensor_collision">
        <pose>-0.078 0 0.167 0 0 0</pose> <!-- Scaled by 1.5 -->
        <geometry>
          <cylinder>
            <radius>0.0762</radius> <!-- Scaled by 1.5 -->
            <length>0.0825</length> <!-- Scaled by 1.5 -->
          </cylinder>
        </geometry>
      </collision>

      <visual name="lidar_sensor_visual">
        <pose>-0.096 0 0.5 0 0 0</pose> <!-- Scaled by 1.5 -->
        <geometry>
          <mesh>
            <uri>model://turtlebot3_common/meshes/lds.dae</uri>
            <scale>0.0015 0.0015 0.0015</scale> <!-- Scaled by 1.5 -->
          </mesh>
        </geometry>
      </visual>

      <sensor name="hls_lfcd_lds" type="ray">
        <always_on>true</always_on>
        <visualize>false</visualize>
        <pose>-0.096 0 0.182 0 0 0</pose> <!-- Scaled by 1.5 -->
        <update_rate>5</update_rate>
        <ray>
          <scan>
            <horizontal>
              <samples>360</samples>
              <resolution>1.000000</resolution>
              <min_angle>0.000000</min_angle>
              <max_angle>6.280000</max_angle>
            </horizontal>
          </scan>
          <range>
            <min>0.180000</min> <!-- Scaled by 1.5 -->
            <max>5.25</max> <!-- Scaled by 1.5 -->
            <resolution>0.022500</resolution> <!-- Scaled by 1.5 -->
          </range>
          <noise>
            <type>gaussian</type>
            <mean>0.0</mean>
            <stddev>0.015</stddev> <!-- Adjusted noise -->
          </noise>
        </ray>
        <plugin name="turtlebot3_laserscan" filename="libgazebo_ros_ray_sensor.so">
          <ros>
            <!-- <namespace>/tb3</namespace> -->
            <remapping>~/out:=scan</remapping>
          </ros>
          <output_type>sensor_msgs/LaserScan</output_type>
          <frame_name>base_scan</frame_name>
        </plugin>
      </sensor>
    </link>

    <link name="wheel_left_link">

      <inertial>
        <pose>0.0 0.144 0.023 -1.57 0 0</pose>
        <inertia>
          <ixx>1.1175580e-05</ixx>
          <ixy>-4.2369783e-11</ixy>
          <ixz>-5.9381719e-09</ixz>
          <iyy>1.1192413e-05</iyy>
          <iyz>-1.4400107e-11</iyz>
          <izz>2.0712558e-05</izz>
        </inertia>
        <mass>0.1</mass>
      </inertial>

      <collision name="wheel_left_collision">
        <pose>0.0 0.144 0.023 -1.57 0 0</pose>
        <geometry>
          <cylinder>
            <radius>0.033</radius>
            <length>0.018</length>
          </cylinder>
        </geometry>
        <surface>
          <!-- This friction pamareter don't contain reliable data!! -->
          <friction>
            <ode>
              <mu>100000.0</mu>
              <mu2>100000.0</mu2>
              <fdir1>0 0 0</fdir1>
              <slip1>0.0</slip1>
              <slip2>0.0</slip2>
            </ode>
          </friction>
          <contact>
            <ode>
              <soft_cfm>0</soft_cfm>
              <soft_erp>0.2</soft_erp>
              <kp>1e+5</kp>
              <kd>1</kd>
              <max_vel>0.01</max_vel>
              <min_depth>0.001</min_depth>
            </ode>
          </contact>
        </surface>
      </collision>

      <visual name="wheel_left_visual">
        <pose>0.0 0.144 0.023 0 0 0</pose>
        <geometry>
          <mesh>
            <uri>model://turtlebot3_common/meshes/tire.dae</uri>
            <scale>0.001 0.001 0.001</scale>
          </mesh>
        </geometry>
      </visual>
    </link>

    <link name="wheel_right_link">

      <inertial>
        <pose>0.0 -0.144 0.023 -1.57 0 0</pose>
        <inertia>
          <ixx>1.1175580e-05</ixx>
          <ixy>-4.2369783e-11</ixy>
          <ixz>-5.9381719e-09</ixz>
          <iyy>1.1192413e-05</iyy>
          <iyz>-1.4400107e-11</iyz>
          <izz>2.0712558e-05</izz>
        </inertia>
        <mass>0.1</mass>
      </inertial>
    
      <collision name="wheel_right_collision">
        <pose>0.0 -0.144 0.023 -1.57 0 0</pose>
        <geometry>
          <cylinder>
            <radius>0.033</radius>
            <length>0.018</length>
          </cylinder>
        </geometry>
        <surface>
          <!-- This friction pamareter don't contain reliable data!! -->
          <friction>
            <ode>
              <mu>100000.0</mu>
              <mu2>100000.0</mu2>
              <fdir1>0 0 0</fdir1>
              <slip1>0.0</slip1>
              <slip2>0.0</slip2>
            </ode>
          </friction>
          <contact>
            <ode>
              <soft_cfm>0</soft_cfm>
              <soft_erp>0.2</soft_erp>
              <kp>1e+5</kp>
              <kd>1</kd>
              <max_vel>0.01</max_vel>
              <min_depth>0.001</min_depth>
            </ode>
          </contact>
        </surface>
      </collision>

      <visual name="wheel_right_visual">
        <pose>0.0 -0.144 0.023 0 0 0</pose>
        <geometry>
          <mesh>
            <uri>model://turtlebot3_common/meshes/tire.dae</uri>
            <scale>0.001 0.001 0.001</scale>
          </mesh>
        </geometry>
      </visual>
    </link>

    <link name='caster_back_right_link'>
      <pose>-0.177 -0.064 -0.004 -1.57 0 0</pose>
      <inertial>
        <mass>0.001</mass>
        <inertia>
          <ixx>0.00001</ixx>
          <ixy>0.000</ixy>
          <ixz>0.000</ixz>
          <iyy>0.00001</iyy>
          <iyz>0.000</iyz>
          <izz>0.00001</izz>
        </inertia>
      </inertial>
      <collision name='collision'>
        <geometry>
          <sphere>
            <radius>0.005000</radius>
          </sphere>
        </geometry>
        <surface>
          <contact>
            <ode>
              <soft_cfm>0</soft_cfm>
              <soft_erp>0.2</soft_erp>
              <kp>1e+5</kp>
              <kd>1</kd>
              <max_vel>0.01</max_vel>
              <min_depth>0.001</min_depth>
            </ode>
          </contact>
        </surface>
      </collision>
    </link>

    <link name='caster_back_left_link'>
      <pose>-0.177 0.064 -0.004 -1.57 0 0</pose>
      <inertial>
        <mass>0.001</mass>
        <inertia>
          <ixx>0.00001</ixx>
          <ixy>0.000</ixy>
          <ixz>0.000</ixz>
          <iyy>0.00001</iyy>
          <iyz>0.000</iyz>
          <izz>0.00001</izz>
        </inertia>
      </inertial>
      <collision name='collision'>
        <geometry>
          <sphere>
            <radius>0.005000</radius>
          </sphere>
        </geometry>
        <surface>
          <contact>
            <ode>
              <soft_cfm>0</soft_cfm>
              <soft_erp>0.2</soft_erp>
              <kp>1e+5</kp>
              <kd>1</kd>
              <max_vel>0.01</max_vel>
              <min_depth>0.001</min_depth>
            </ode>
          </contact>
        </surface>
      </collision>
    </link>

    <link name="camera_link"/>

    <link name="camera_rgb_frame">
      <inertial>
        <pose>0.069 -0.047 0.107 0 0 0</pose>
        <inertia>
          <ixx>0.001</ixx>
          <ixy>0.000</ixy>
          <ixz>0.000</ixz>
          <iyy>0.001</iyy>
          <iyz>0.000</iyz>
          <izz>0.001</izz>
        </inertia>
        <mass>0.035</mass>
      </inertial>

      <pose>0.069 -0.047 0.107 0 0 0</pose>
      <sensor name="camera" type="depth">
       <pose> 0 0 0 0 0 0 </pose>
        <always_on>true</always_on>
        <visualize>true</visualize>
        <update_rate>1</update_rate>
        <camera name="intel_realsense_r200">
           <horizontal_fov>1.02974</horizontal_fov>
          <image>
            <width>640</width>
            <height>480</height>
            <format>B8G8R8</format>
          </image>
          <clip>
               <near>0.05</near>
               <far>8.0</far>
          </clip>
          <noise>
            <type>gaussian</type>

            <mean>0.0</mean>
            <stddev>0.007</stddev>
          </noise>
        </camera>
          <plugin name="camera_driver" filename="libgazebo_ros_camera.so">
            <ros>
            </ros>
          <frame_name>camera_rgb_frame</frame_name>
          <min_depth>0.1</min_depth>
          <max_depth>100</max_depth>

          </plugin>
      </sensor>
    </link>

    
<!--
  <link name="turtlebot3_wall1">
      <visual name="turtlebot3_wall1_visual">>
        <pose>-0.0 0 0 0 0 0</pose>
        <geometry>
         <box>
            <size>0.25 0.25 0.005</size>
         </box>
        </geometry>

        <material>Gazebo/Red</material>
      </visual>
      <collision name="turtlebot3_wall1_collision">
        <pose>-0.0 0 .0 0 0 0</pose>
        <geometry>
          <box>
            <size>0.25 0.25 0.005</size>
         </box>
        </geometry>
      </collision>
    </link>

  <joint name="turtlebot3_wall1_joint" type="fixed">
    <parent>turtlebot3_tray</parent>
      <child>turtlebot3_wall1</child>
    <pose>0.0 0.0 0.0 1.57 1.57 0</pose>
  </joint>
  -->

    <joint name="base_joint" type="fixed">
      <parent>base_footprint</parent>
      <child>base_link</child>
    </joint>

    <joint name="wheel_left_joint" type="revolute">
      <parent>base_link</parent>
      <child>wheel_left_link</child>
      <pose>0.0 0.144 0.023 -1.57 0 0</pose>
      <axis>
        <xyz>0 0 1</xyz>
      </axis>
    </joint>

    <joint name="wheel_right_joint" type="revolute">
      <parent>base_link</parent>
      <child>wheel_right_link</child>
      <pose>0.0 -0.144 0.023 -1.57 0 0</pose>
      <axis>
        <xyz>0 0 1</xyz>
      </axis>
    </joint>

    <joint name='caster_back_right_joint' type='ball'>
      <parent>base_link</parent>
      <child>caster_back_right_link</child>
    </joint>

    <joint name='caster_back_left_joint' type='ball'>
      <parent>base_link</parent>
      <child>caster_back_left_link</child>
    </joint>

    <joint name="imu_joint" type="fixed">
      <parent>base_link</parent>
      <child>imu_link</child>
      <pose>-0.032 0 0.068 0 0 0</pose>
      <axis>
        <xyz>0 0 1</xyz>
      </axis>
    </joint>    

    <joint name="lidar_joint" type="fixed">
      <parent>base_link</parent>
      <child>base_scan</child>
      <pose>-0.096 0 0.182 0 0 0</pose> <!-- Scaled by 1.5 -->
      <axis>
        <xyz>0 0 1</xyz>
      </axis>
    </joint>

    <joint name="camera_joint" type="fixed">
      <parent>base_link</parent>
      <child>camera_link</child>
      <pose>0.064 -0.065 0.094 0 0 0</pose>
      <axis>
        <xyz>0 0 1</xyz>
      </axis>
    </joint>

    <joint name="camera_rgb_joint" type="fixed">
      <parent>camera_link</parent>
      <child>camera_rgb_frame</child>
      <pose>0.005 0.018 0.013 1 0 0</pose>
      <axis>
        <xyz>0 0 1</xyz>
      </axis>
    </joint>

    <plugin name="turtlebot3_diff_drive" filename="libgazebo_ros_diff_drive.so">

      <ros>
        <!-- <namespace>/robot0</namespace> -->
        <remapping>/tf:=tf</remapping>
      </ros>

      <update_rate>30</update_rate>
      <left_joint>wheel_left_joint</left_joint>
      <right_joint>wheel_right_joint</right_joint>

      <wheel_separation>0.287</wheel_separation>
      <wheel_diameter>0.066</wheel_diameter>

      <max_wheel_torque>20</max_wheel_torque>
      <max_wheel_acceleration>1.0</max_wheel_acceleration>

      <command_topic>cmd_vel</command_topic>

      <publish_odom>true</publish_odom>
      <publish_odom_tf>true</publish_odom_tf>
      <publish_wheel_tf>false</publish_wheel_tf>

      <odometry_topic>odom</odometry_topic>
      <odometry_frame>odom</odometry_frame>
      <robot_base_frame>base_footprint</robot_base_frame>

    </plugin>

    <plugin name="turtlebot3_joint_state" filename="libgazebo_ros_joint_state_publisher.so">
      <ros>
        <!-- <namespace>/tb3</namespace> -->
        <remapping>~/out:=joint_states</remapping>
      </ros>
      <update_rate>30</update_rate>
      <joint_name>wheel_left_joint</joint_name>
      <joint_name>wheel_right_joint</joint_name>
    </plugin>    

      <!-- Left Fork -->
    <link name="fork_left_link">
      <inertial>
        <pose>0.2 0.1 0.05 0 0 0</pose>
        <mass>0.5</mass>
        <inertia>
          <ixx>0.001</ixx>
          <ixy>0</ixy>
          <ixz>0</ixz>
          <iyy>0.001</iyy>
          <iyz>0</iyz>
          <izz>0.001</izz>
        </inertia>
      </inertial>
      <collision name="fork_left_collision">
        <pose>0.2 0.1 0.05 0 0 0</pose>
        <geometry>
          <box>
            <size>0.4 0.05 0.01</size>
          </box>
        </geometry>
      </collision>
      <visual name="fork_left_visual">
        <pose>0.2 0.25 0.05 0 0 0</pose>
        <geometry>
          <box>
            <size>1 0.15 0.02</size>
          </box>
        </geometry>
        <material>
            <ambient>0.5 0.5 0.5 1</ambient>
            <diffuse>0.5 0.5 0.5 1</diffuse>
            <specular>0.5 0.5 0.5 1</specular>
  
        </material>
      </visual>
    </link>

    <!-- Right Fork -->
    <link name="fork_right_link">
      <inertial>
        <pose>0.2 -0.1 0.05 0 0 0</pose>
        <mass>0.5</mass>
        <inertia>
          <ixx>0.001</ixx>
          <ixy>0</ixy>
          <ixz>0</ixz>
          <iyy>0.001</iyy>
          <iyz>0</iyz>
          <izz>0.001</izz>
        </inertia>
      </inertial>
      <collision name="fork_right_collision">
        <pose>0.2 -0.1 0.05 0 0 0</pose>
        <geometry>
          <box>
            <size>0.4 0.05 0.01</size>
          </box>
        </geometry>
      </collision>
      <visual name="fork_right_visual">
        <pose>0.1 -0.25 0.05 0 0 0</pose>
        <geometry>
          <box>
            <size>1.5 0.15 0.02</size>
          </box>
        </geometry>
        <material>
            <ambient>0.5 0.5 0.5 1</ambient>
            <diffuse>0.5 0.5 0.5 1</diffuse>
            <specular>0.5 0.5 0.5 1</specular>
        </material>
      </visual>
    </link>

    <!-- Left Fork Joint -->
    <joint name="fork_left_joint" type="prismatic">
      <parent>base_link</parent>
      <child>fork_left_link</child>
      <pose>0 0 0 0 0 0</pose>
      <axis>
        <xyz>0 0 1</xyz>
        <limit>
          <lower>0</lower>
          <upper>0.3</upper>
          <effort>100</effort>
          <velocity>0.1</velocity>
        </limit>
        <dynamics>
          <damping>50</damping>
          <friction>1</friction>
        </dynamics>
      </axis>
    </joint>

    <!-- Right Fork Joint -->
    <joint name="fork_right_joint" type="prismatic">
      <parent>base_link</parent>
      <child>fork_right_link</child>
      <pose>0 0 0 0 0 0</pose>
      <axis>
        <xyz>0 0 1</xyz>
        <limit>
          <lower>0</lower>
          <upper>0.3</upper>
          <effort>100</effort>
          <velocity>0.1</velocity>
        </limit>
        <dynamics>
          <damping>50</damping>
          <friction>1</friction>
        </dynamics>
      </axis>
    </joint>

  </model>
</sdf>
